"""
This is the "example" module.

The example module supplies one function, factorial().  For example,

>>> factorial(5)
120
"""

def factorial(n):
    """Return the factorial of n, an exact integer >= 0.

    If the result is small enough to fit in an int, return an int.
    Else return a long.

    >>> [factorial(n) for n in range(6)]
    [1, 1, 2, 6, 24, 120]
    >>> [factorial(long(n)) for n in range(6)]
    [1, 1, 2, 6, 24, 120]
    >>> factorial(30)
    265252859812191058636308480000000L
    >>> factorial(30L)
    265252859812191058636308480000000L
    >>> factorial(-1)
    Traceback (most recent call last):
        ...
    ValueError: n must be >= 0

    Factorials of floats are OK, but the float must be an exact integer:
    >>> factorial(30.1)
    Traceback (most recent call last):
        ...
    ValueError: n must be exact integer
    >>> factorial(30.0)
    265252859812191058636308480000000L

    It must also not be ridiculously large:
    >>> factorial(1e100)
    Traceback (most recent call last):
        ...
    OverflowError: n too large
    """

    import math
    
    '''
    [06/02/2014]
    ICI, que je passe par 'print' (A) ou 'sys.stdout.write' (B), ca pollue la valeur de retour
    et ca fausse le resultat attendu !
    Ca n'est pas que l'une ou l'autre primitive ecrive dans le "result".
    Mais c'est plutot le fonctionnement du "doctest" qui capte tout, et meme ce qu'il ne faudrait pas...
    '''  
    # A)
    #print "in factorial() for ", n
    
    # B)
    #import sys
    #sys.stdout.write("in factorial() for "+ str(n))

    
    if not n >= 0:
        raise ValueError("n must be >= 0")
    if math.floor(n) != n:
        raise ValueError("n must be exact integer")
    if n+1 == n:  # catch a value like 1e300
        raise OverflowError("n too large")
    result = 1
    factor = 2
    while factor <= n:
        result *= factor
        factor += 1
    return result


if __name__ == "__main__":
    import doctest
    doctest.testmod()